{"uuid": "929fef7a-c023-4631-8824-3758e0c74246", "children": ["3d335703-1b8a-4a7f-a915-50198a1422f4"], "befores": [{"name": "driver", "status": "broken", "statusDetails": {"message": "urllib3.exceptions.MaxRetryError: HTTPConnectionPool(host='localhost', port=4723): Max retries exceeded with url: /wd/hub/session (Caused by NewConnectionError('<urllib3.connection.HTTPConnection object at 0x0000021EC8FF5E80>: Failed to establish a new connection: [WinError 10061] Подключение не установлено, т.к. конечный компьютер отверг запрос на подключение'))\n", "trace": "  File \"C:\\Users\\ilnazhim\\Appium\\SosediService\\venv\\lib\\site-packages\\pluggy\\_callers.py\", line 39, in _multicall\n    res = hook_impl.function(*args)\n  File \"C:\\Users\\ilnazhim\\Appium\\SosediService\\venv\\lib\\site-packages\\_pytest\\fixtures.py\", line 1129, in pytest_fixture_setup\n    result = call_fixture_func(fixturefunc, request, kwargs)\n  File \"C:\\Users\\ilnazhim\\Appium\\SosediService\\venv\\lib\\site-packages\\_pytest\\fixtures.py\", line 901, in call_fixture_func\n    fixture_result = next(generator)\n  File \"C:\\Users\\ilnazhim\\Appium\\SosediService\\conftest.py\", line 17, in driver\n    driver = webdriver.Remote(\"http://localhost:4723/wd/hub\", desired_cap)\n  File \"C:\\Users\\ilnazhim\\Appium\\SosediService\\venv\\lib\\site-packages\\appium\\webdriver\\webdriver.py\", line 230, in __init__\n    super().__init__(\n  File \"C:\\Users\\ilnazhim\\Appium\\SosediService\\venv\\lib\\site-packages\\selenium\\webdriver\\remote\\webdriver.py\", line 286, in __init__\n    self.start_session(capabilities, browser_profile)\n  File \"C:\\Users\\ilnazhim\\Appium\\SosediService\\venv\\lib\\site-packages\\appium\\webdriver\\webdriver.py\", line 320, in start_session\n    response = self.execute(RemoteCommand.NEW_SESSION, w3c_caps)\n  File \"C:\\Users\\ilnazhim\\Appium\\SosediService\\venv\\lib\\site-packages\\selenium\\webdriver\\remote\\webdriver.py\", line 438, in execute\n    response = self.command_executor.execute(driver_command, params)\n  File \"C:\\Users\\ilnazhim\\Appium\\SosediService\\venv\\lib\\site-packages\\selenium\\webdriver\\remote\\remote_connection.py\", line 290, in execute\n    return self._request(command_info[0], url, body=data)\n  File \"C:\\Users\\ilnazhim\\Appium\\SosediService\\venv\\lib\\site-packages\\selenium\\webdriver\\remote\\remote_connection.py\", line 311, in _request\n    response = self._conn.request(method, url, body=body, headers=headers)\n  File \"C:\\Users\\ilnazhim\\Appium\\SosediService\\venv\\lib\\site-packages\\urllib3\\request.py\", line 78, in request\n    return self.request_encode_body(\n  File \"C:\\Users\\ilnazhim\\Appium\\SosediService\\venv\\lib\\site-packages\\urllib3\\request.py\", line 170, in request_encode_body\n    return self.urlopen(method, url, **extra_kw)\n  File \"C:\\Users\\ilnazhim\\Appium\\SosediService\\venv\\lib\\site-packages\\urllib3\\poolmanager.py\", line 376, in urlopen\n    response = conn.urlopen(method, u.request_uri, **kw)\n  File \"C:\\Users\\ilnazhim\\Appium\\SosediService\\venv\\lib\\site-packages\\urllib3\\connectionpool.py\", line 815, in urlopen\n    return self.urlopen(\n  File \"C:\\Users\\ilnazhim\\Appium\\SosediService\\venv\\lib\\site-packages\\urllib3\\connectionpool.py\", line 815, in urlopen\n    return self.urlopen(\n  File \"C:\\Users\\ilnazhim\\Appium\\SosediService\\venv\\lib\\site-packages\\urllib3\\connectionpool.py\", line 815, in urlopen\n    return self.urlopen(\n  File \"C:\\Users\\ilnazhim\\Appium\\SosediService\\venv\\lib\\site-packages\\urllib3\\connectionpool.py\", line 787, in urlopen\n    retries = retries.increment(\n  File \"C:\\Users\\ilnazhim\\Appium\\SosediService\\venv\\lib\\site-packages\\urllib3\\util\\retry.py\", line 592, in increment\n    raise MaxRetryError(_pool, url, error or ResponseError(cause))\n"}, "start": 1679581966101, "stop": 1679581982446}], "start": 1679581966101, "stop": 1679581982762}